[rank0]: Traceback (most recent call last):
[rank0]:   File "/global/u1/l/lokeshb/E2E/E2E_MAE_Lokesh_Badisa/dist-training.py", line 282, in <module>
[rank0]:     main(args)
[rank0]:   File "/global/u1/l/lokeshb/E2E/E2E_MAE_Lokesh_Badisa/dist-training.py", line 274, in main
[rank0]:     trainer.train(args.epochs)
[rank0]:   File "/global/u1/l/lokeshb/E2E/E2E_MAE_Lokesh_Badisa/dist-training.py", line 214, in train
[rank0]:     loss, dsize = self._run_epoch(epoch)
[rank0]:   File "/global/u1/l/lokeshb/E2E/E2E_MAE_Lokesh_Badisa/dist-training.py", line 183, in _run_epoch
[rank0]:     data = data.to(self.global_rank)
[rank0]: RuntimeError: CUDA error: invalid device ordinal
[rank0]: Compile with `TORCH_USE_CUDA_DSA` to enable device-side assertions.

[rank0]: Traceback (most recent call last):
[rank0]:   File "/global/u1/l/lokeshb/E2E/E2E_MAE_Lokesh_Badisa/dist-training.py", line 282, in <module>
[rank0]:     main(args)
[rank0]:   File "/global/u1/l/lokeshb/E2E/E2E_MAE_Lokesh_Badisa/dist-training.py", line 274, in main
[rank0]:     trainer.train(args.epochs)
[rank0]:   File "/global/u1/l/lokeshb/E2E/E2E_MAE_Lokesh_Badisa/dist-training.py", line 214, in train
[rank0]:     loss, dsize = self._run_epoch(epoch)
[rank0]:   File "/global/u1/l/lokeshb/E2E/E2E_MAE_Lokesh_Badisa/dist-training.py", line 183, in _run_epoch
[rank0]:     data = data.to(self.global_rank)
[rank0]: RuntimeError: CUDA error: invalid device ordinal
[rank0]: Compile with `TORCH_USE_CUDA_DSA` to enable device-side assertions.

[rank0]: Traceback (most recent call last):
[rank0]:   File "/global/u1/l/lokeshb/E2E/E2E_MAE_Lokesh_Badisa/dist-training.py", line 282, in <module>
[rank0]:     main(args)
[rank0]:   File "/global/u1/l/lokeshb/E2E/E2E_MAE_Lokesh_Badisa/dist-training.py", line 274, in main
[rank0]:     trainer.train(args.epochs)
[rank0]:   File "/global/u1/l/lokeshb/E2E/E2E_MAE_Lokesh_Badisa/dist-training.py", line 214, in train
[rank0]:     loss, dsize = self._run_epoch(epoch)
[rank0]:   File "/global/u1/l/lokeshb/E2E/E2E_MAE_Lokesh_Badisa/dist-training.py", line 183, in _run_epoch
[rank0]:     data = data.to(self.global_rank)
[rank0]: RuntimeError: CUDA error: invalid device ordinal
[rank0]: Compile with `TORCH_USE_CUDA_DSA` to enable device-side assertions.

  0%|          | 0/1 [00:00<?, ?it/s]
E0827 15:58:27.610000 139690264589440 torch/distributed/elastic/multiprocessing/api.py:826] failed (exitcode: 1) local_rank: 0 (pid: 2102705) of binary: /usr/bin/python
E0827 15:58:27.612000 140641203205248 torch/distributed/elastic/multiprocessing/api.py:826] failed (exitcode: 1) local_rank: 0 (pid: 2102706) of binary: /usr/bin/python
Traceback (most recent call last):
  File "/usr/local/bin/torchrun", line 33, in <module>
    sys.exit(load_entry_point('torch==2.4.0a0+07cecf4168.nv24.5', 'console_scripts', 'torchrun')())
  File "/usr/local/lib/python3.10/dist-packages/torch/distributed/elastic/multiprocessing/errors/__init__.py", line 347, in wrapper
    return f(*args, **kwargs)
  File "/usr/local/lib/python3.10/dist-packages/torch/distributed/run.py", line 879, in main
    run(args)
  File "/usr/local/lib/python3.10/dist-packages/torch/distributed/run.py", line 870, in run
    elastic_launch(
  File "/usr/local/lib/python3.10/dist-packages/torch/distributed/launcher/api.py", line 132, in __call__
    return launch_agent(self._config, self._entrypoint, list(args))
  File "/usr/local/lib/python3.10/dist-packages/torch/distributed/launcher/api.py", line 263, in launch_agent
    raise ChildFailedError(
torch.distributed.elastic.multiprocessing.errors.ChildFailedError: 
============================================================
dist-training.py FAILED
------------------------------------------------------------
Failures:
  <NO_OTHER_FAILURES>
------------------------------------------------------------
Root Cause (first observed failure):
[0]:
  time      : 2024-08-27_15:58:27
  host      : nid002701-hsn0
  rank      : 0 (local_rank: 0)
  exitcode  : 1 (pid: 2102705)
  error_file: <N/A>
  traceback : To enable traceback see: https://pytorch.org/docs/stable/elastic/errors.html
============================================================
Traceback (most recent call last):
  File "/usr/local/bin/torchrun", line 33, in <module>
    sys.exit(load_entry_point('torch==2.4.0a0+07cecf4168.nv24.5', 'console_scripts', 'torchrun')())
  File "/usr/local/lib/python3.10/dist-packages/torch/distributed/elastic/multiprocessing/errors/__init__.py", line 347, in wrapper
    return f(*args, **kwargs)
  File "/usr/local/lib/python3.10/dist-packages/torch/distributed/run.py", line 879, in main
    run(args)
  File "/usr/local/lib/python3.10/dist-packages/torch/distributed/run.py", line 870, in run
    elastic_launch(
  File "/usr/local/lib/python3.10/dist-packages/torch/distributed/launcher/api.py", line 132, in __call__
    return launch_agent(self._config, self._entrypoint, list(args))
  File "/usr/local/lib/python3.10/dist-packages/torch/distributed/launcher/api.py", line 263, in launch_agent
    raise ChildFailedError(
torch.distributed.elastic.multiprocessing.errors.ChildFailedError: 
============================================================
dist-training.py FAILED
------------------------------------------------------------
Failures:
  <NO_OTHER_FAILURES>
------------------------------------------------------------
Root Cause (first observed failure):
[0]:
  time      : 2024-08-27_15:58:27
  host      : nid002701-hsn0
  rank      : 0 (local_rank: 0)
  exitcode  : 1 (pid: 2102706)
  error_file: <N/A>
  traceback : To enable traceback see: https://pytorch.org/docs/stable/elastic/errors.html
============================================================
E0827 15:58:27.844000 139783678977152 torch/distributed/elastic/multiprocessing/api.py:826] failed (exitcode: 1) local_rank: 0 (pid: 2102711) of binary: /usr/bin/python
Traceback (most recent call last):
  File "/usr/local/bin/torchrun", line 33, in <module>
    sys.exit(load_entry_point('torch==2.4.0a0+07cecf4168.nv24.5', 'console_scripts', 'torchrun')())
  File "/usr/local/lib/python3.10/dist-packages/torch/distributed/elastic/multiprocessing/errors/__init__.py", line 347, in wrapper
    return f(*args, **kwargs)
  File "/usr/local/lib/python3.10/dist-packages/torch/distributed/run.py", line 879, in main
    run(args)
  File "/usr/local/lib/python3.10/dist-packages/torch/distributed/run.py", line 870, in run
    elastic_launch(
  File "/usr/local/lib/python3.10/dist-packages/torch/distributed/launcher/api.py", line 132, in __call__
    return launch_agent(self._config, self._entrypoint, list(args))
  File "/usr/local/lib/python3.10/dist-packages/torch/distributed/launcher/api.py", line 263, in launch_agent
    raise ChildFailedError(
torch.distributed.elastic.multiprocessing.errors.ChildFailedError: 
============================================================
dist-training.py FAILED
------------------------------------------------------------
Failures:
  <NO_OTHER_FAILURES>
------------------------------------------------------------
Root Cause (first observed failure):
[0]:
  time      : 2024-08-27_15:58:27
  host      : nid002701-hsn0
  rank      : 0 (local_rank: 0)
  exitcode  : 1 (pid: 2102711)
  error_file: <N/A>
  traceback : To enable traceback see: https://pytorch.org/docs/stable/elastic/errors.html
============================================================
srun: error: nid002701: tasks 2-3: Exited with exit code 1
srun: Terminating StepId=29860492.0
  0%|          | 0/3102 [00:00<?, ?it/s][Aslurmstepd: error: *** STEP 29860492.0 ON nid002701 CANCELLED AT 2024-08-27T15:58:28 ***
W0827 15:58:28.961000 139781069427840 torch/distributed/elastic/agent/server/api.py:741] Received Signals.SIGTERM death signal, shutting down workers
W0827 15:58:28.961000 139781069427840 torch/distributed/elastic/multiprocessing/api.py:851] Sending process 2102708 closing signal SIGTERM
srun: error: nid002701: task 1: Exited with exit code 1
Traceback (most recent call last):
  File "/usr/local/bin/torchrun", line 33, in <module>
    sys.exit(load_entry_point('torch==2.4.0a0+07cecf4168.nv24.5', 'console_scripts', 'torchrun')())
  File "/usr/local/lib/python3.10/dist-packages/torch/distributed/elastic/multiprocessing/errors/__init__.py", line 347, in wrapper
    return f(*args, **kwargs)
  File "/usr/local/lib/python3.10/dist-packages/torch/distributed/run.py", line 879, in main
    run(args)
  File "/usr/local/lib/python3.10/dist-packages/torch/distributed/run.py", line 870, in run
    elastic_launch(
  File "/usr/local/lib/python3.10/dist-packages/torch/distributed/launcher/api.py", line 132, in __call__
    return launch_agent(self._config, self._entrypoint, list(args))
  File "/usr/local/lib/python3.10/dist-packages/torch/distributed/launcher/api.py", line 254, in launch_agent
    result = agent.run()
  File "/usr/local/lib/python3.10/dist-packages/torch/distributed/elastic/metrics/api.py", line 123, in wrapper
    result = f(*args, **kwargs)
  File "/usr/local/lib/python3.10/dist-packages/torch/distributed/elastic/agent/server/api.py", line 733, in run
    result = self._invoke_run(role)
  File "/usr/local/lib/python3.10/dist-packages/torch/distributed/elastic/agent/server/api.py", line 876, in _invoke_run
    time.sleep(monitor_interval)
  File "/usr/local/lib/python3.10/dist-packages/torch/distributed/elastic/multiprocessing/api.py", line 76, in _terminate_process_handler
    raise SignalException(f"Process {os.getpid()} got signal: {sigval}", sigval=sigval)
torch.distributed.elastic.multiprocessing.api.SignalException: Process 2102563 got signal: 15
srun: error: nid002701: task 0: Exited with exit code 1
